Workbook

Sheet Data Entry
A1: DATA ENTRY
K4: Initials of person entering data: | M4: Initials of person checking data:
A6: Phase | B6: Baseline | E6: IOA | F6: Power Ups | G6: Freq | H6: Power Ups | I6: Freq
A7: Trial Type | B7: Baseline | C7: Resp per Min | F7: Barrel Roll | G7: #N/A | H7: Flame Change | I7: #N/A
A8: Session | B8: 1 | C8: =B9 | E8: IOA | F8: Spins | G8: #N/A | H8: Red token | I8: #N/A
A9: Target Resp | B9: #N/A | E9: Y/E | F9: Speed Boosts | G9: #N/A | H9: Blue Token | I9: #N/A
A10: Asteroids | B10: #N/A | C10: Reinf per Min | E10: Y/E | F10: Coin Boost | G10: #N/A | H10: Yellow Token | I10: #N/A
A11: Total Points: | B11: #N/A | C11: =((B11/5)) | E11: Y/E | H11: Crash | I11: #N/A | AI11: Alt 1 | AJ11: Alt 2 | AK11: target 1 | AL11: Target 2
A13: Phase | B13: Baseline | F13: Power Ups | G13: Freq | H13: Power Ups | I13: Freq | AH13: 2 | AI13: 0.288 | AJ13: 1.9920949 | AK13: 0.31034483 | AL13: 0.051724138
A14: Trial Type | B14: Baseline | C14: Resp per Min | F14: Barrel Roll | G14: #N/A | H14: Flame Change | I14: #N/A | AH14: 3 | AI14: 0.192 | AJ14: 0.45059289 | AK14: 0.077586207 | AL14: 0.025862069
A15: Session | B15: =B8+1 | C15: =B16 | E15: IOA | F15: Spins | G15: #N/A | H15: Red token | I15: #N/A
A16: Target Resp | B16: #N/A | E16: Y/E | F16: Speed Boosts | G16: #N/A | H16: Blue Token | I16: #N/A | AH16: Slope | AI16: -0.672 | AJ16: -0.65217391 | AK16: -0.86637931 | AL16: -0.064655172
A17: Asteroids | B17: #N/A | C17: Reinf per Min | E17: Y/E | F17: Coin Boost | G17: #N/A | H17: Yellow Token | I17: #N/A
A18: Total Points: | B18: #N/A | C18: =(((B18-B11)/5)) | D18: =B18/5 | E18: Y/E | H18: Crash | I18: #N/A | AH18: N | AI18: 3 | AJ18: 3 | AK18: 3 | AL18: 3
AH19: Se(reg) | AI19: 0.47030203 | AJ19: 0.72613332 | AK19: 0.51734913 | AL19: 0.031674436
A20: Phase | B20: Baseline | F20: Power Ups | G20: Freq | H20: Power Ups | I20: Freq | AH20: SE (slope) | AI20: 0.33255376 | AJ20: 0.5134538 | AK20: 0.36582108 | AL20: 0.022397209
A21: Trial Type | B21: Baseline | C21: Resp per Min | F21: Barrel Roll | G21: #N/A | H21: Flame Change | I21: #N/A | AI21: Dif | AJ21: 0.019826087 | AK21: Dif | AL21: 0.80172414
A22: Session | B22: =B15+1 | C22: =B23 | E22: IOA | F22: Spins | G22: #N/A | H22: Red token | I22: #N/A | AI22: SE (Dif) | AJ22: 0.6117408 | AK22: SE (Dif) | AL22: 0.36650606
A23: Target Resp | B23: #N/A | E23: Y/E | F23: Speed Boosts | G23: #N/A | H23: Blue Token | I23: #N/A | AI23: T-stat | AJ23: 0.032409293 | AK23: T-stat | AL23: 2.1874785
A24: Asteroids | B24: #N/A | C24: Reinf per Min | E24: Y/E | F24: Coin Boost | G24: #N/A | H24: Yellow Token | I24: #N/A
A25: Total Points: | B25: #N/A | C25: =(((B25-B18)/5)) | D25: =B25/5 | E25: Y/E | H25: Crash | I25: #N/A | AI25: DF | AJ25: 4 | AK25: DF | AL25: 4
AI26: P | AJ26: 0.97569835 | AK26: P | AL26: 0.093956212
A27: Phase | B27: Baseline | F27: Power Ups | G27: Freq | H27: Power Ups | I27: Freq
A28: Trial Type | B28: Baseline | C28: Resp per Min | F28: Barrel Roll | G28: #N/A | H28: Flame Change | I28: #N/A
A29: Session | B29: =B22+1 | C29: =B30 | E29: IOA | F29: Spins | G29: #N/A | H29: Red token | I29: #N/A
A30: Target Resp | B30: #N/A | E30: Y/E | F30: Speed Boosts | G30: #N/A | H30: Blue Token | I30: #N/A
A31: Alt resp | B31: #N/A | C31: =B31 | E31: Y/E | F31: Coin Boost | G31: #N/A | H31: Yellow Token | I31: #N/A
A32: Asteroids | B32: #N/A | C32: Reinf per Min | E32: Y/E | H32: Crash | I32: #N/A
A33: Total Points: | B33: #N/A | C33: =(((B33-B25)/5)) | D33: =B33/5 | E33: Y/E
A35: Phase | B35: Treatment | F35: Power Ups | G35: Freq | H35: Power Ups | I35: Freq
A36: Trial Type | B36: Treatment | C36: Resp per Min | F36: Barrel Roll | G36: #N/A | H36: Flame Change | I36: #N/A
A37: Session | B37: =B29+1 | C37: =B38 | E37: IOA | F37: Spins | G37: #N/A | H37: Red token | I37: #N/A
A38: Target Resp | B38: #N/A | E38: Y/E | F38: Speed Boosts | G38: #N/A | H38: Blue Token | I38: #N/A
A39: Alt Resp | B39: #N/A | C39: =B39 | E39: Y/E | F39: Coin Boost | G39: #N/A | H39: Yellow Token | I39: #N/A
A40: Asteroids | B40: #N/A | C40: Reinf per Min | E40: Y/E | H40: Crash | I40: #N/A
A41: Total Points: | B41: #N/A | C41: =(((B41-B33)/5)) | D41: =B41/5 | E41: Y/E
A44: Phase | B44: Treatment | C44: Responses/Reinf Per Min | F44: Power Ups | G44: Freq | H44: Power Ups | I44: Freq
A45: Trial Type | B45: Treatment | F45: Barrel Roll | G45: #N/A | H45: Flame Change | I45: #N/A
A46: Session | B46: =B37+1 | E46: IOA | F46: Spins | G46: #N/A | H46: Red token | I46: #N/A
A47: Target Resp | B47: #N/A | C47: =B47 | E47: Y/E | F47: Speed Boosts | G47: #N/A | H47: Blue Token | I47: #N/A
...

Sheet Data Entry 1
D2: Target | E2: Alt | F2: Asteroids | G2: Score | H2: Barrels | I2: Spins | J2: Turbo | K2: Coin Boost | L2: Flame Change | M2: Red Gem | N2: Blue Gem | O2: Yellow Gem | P2: Crash | R2: Target | S2: Alt | T2: Asteroids | U2: Score | V2: Barrels | W2: Spins | X2: Turbo | Y2: Coin Boost | Z2: Flame Change | AA2: Red Gem | AB2: Blue Gem | AC2: Yellow Gem | AD2: Total Gems | AE2: Combined PU | AF2: Crash | AJ2: Phase Lines | AM2: Dotted PL
A3: Session | B3: Duration | C3: Condition | D3: Freq | E3: Freq | F3: Freq | G3: Total | H3: Freq | I3: Freq | J3: Freq | K3: Freq | L3: Freq | M3: Freq | N3: Freq | O3: Freq | P3: Freq | R3: Rate | S3: Rate | T3: Rate | U3: Rate | V3: Rate | W3: Rate | X3: Rate | Y3: Rate | Z3: Rate | AA3: Rate | AB3: Rate | AC3: Rate | AD3: Rate | AE3: Rate | AF3: Rate | AJ3: 4.5 | AK3: 0 | AM3: 11.5 | AN3: 0
A4: 1 | B4: 1 | C4: 1 | D4: 18 | E4: 0 | F4: 34 | G4: 35 | H4: 2 | I4: 2 | J4: 1 | K4: 1 | L4: 1 | M4: 0 | N4: 1 | O4: 1 | P4: 4 | R4: =D4/$B4 | S4: =E4/$B4 | T4: =F4/$B4 | U4: =G4/$B4 | V4: =H4/$B4 | W4: =I4/$B4 | X4: =J4/$B4 | Y4: =K4/$B4 | ... AC4: =O4/$B4 | AD4: =(M4+N4+O4)/B4 | AE4: =(F4+I4+J4+K4+L4+M4+N4+O4)/$B4 | AF4: =P4/$B4 | AJ4: 4.5 | AK4: 1000 | AM4: 11.5 | AN4: 1000
A5: 2 | B5: 1 | C5: 1 | D5: 0 | E5: 0 | F5: 5 | G5: 35 | H5: 2 | I5: 0 | J5: 0 | K5: 0 | L5: 1 | M5: 0 | N5: 0 | O5: 0 | P5: 0 | R5: =D5/$B5 | S5: =E5/$B5 | T5: =F5/$B5 | U5: =G5-G4/$B5 | V5: =H5/$B5 | W5: =I5/$B5 | X5: =J5/$B5 | Y5: =K5/$B5 | Z5: =L5/$B5 | AA5: =M5/$B5 | AB5: =N5/$B5 | AC5: =O5/$B5 | AD5: =(M5+N5+O5)/B5 | AE5: =(F5+I5+J5+K5+L5+M5+N5+O5)/$B5 | AF5: =P5/$B5
A6: 3 | B6: 1 | C6: 1 | D6: 16 | E6: 0 | F6: 12 | G6: 75 | H6: 2 | I6: 3 | J6: 0 | K6: 0 | L6: 1 | M6: 1 | N6: 0 | O6: 0 | P6: 32 | R6: =D6/$B6 | S6: =E6/$B6 | T6: =F6/$B6 | U6: =G6-G5/$B6 | V6: =H6/$B6 | W6: =I6/$B6 | X6: =J6/$B6 | Y6: =K6/$B6 | Z6: =L6/$B6 | AA6: =M6/$B6 | AB6: =N6/$B6 | AC6: =O6/$B6 | AD6: =(M6+N6+O6)/B6 | AE6: =(F6+I6+J6+K6+L6+M6+N6+O6)/$B6 | AF6: =P6/$B6 | AJ6: 7.5 | AK6: 0 | AM6: 12.5 | AN6: 0
A7: 4 | B7: 1 | C7: 1 | D7: 0 | E7: 0 | F7: 3 | G7: 75 | H7: 1 | I7: 0 | J7: 0 | K7: 0 | L7: 0 | M7: 0 | N7: 1 | O7: 0 | P7: 0 | R7: =D7/$B7 | S7: =E7/$B7 | T7: =F7/$B7 | U7: =G7-G6/$B7 | V7: =H7/$B7 | W7: =I7/$B7 | X7: =J7/$B7 | Y7: =K7/$B7 | Z7: =L7/$B7 | AA7: =M7/$B7 | AB7: =N7/$B7 | AC7: =O7/$B7 | AD7: =(M7+N7+O7)/B7 | AE7: =(F7+I7+J7+K7+L7+M7+N7+O7)/$B7 | AF7: =P7/$B7 | AJ7: 7.5 | AK7: 1000 | AM7: 12.5 | AN7: 1000
A8: 5 | B8: 1 | C8: 2 | D8: 4 | E8: 7 | F8: 18 | G8: 90 | H8: 3 | I8: 0 | J8: 0 | K8: 1 | L8: 1 | M8: 0 | N8: 0 | O8: 0 | P8: 0 | R8: =D8/$B8 | S8: =E8/$B8 | T8: =F8/$B8 | U8: =G8-G7/$B8 | V8: =H8/$B8 | W8: =I8/$B8 | X8: =J8/$B8 | Y8: =K8/$B8 | Z8: =L8/$B8 | AA8: =M8/$B8 | AB8: =N8/$B8 | AC8: =O8/$B8 | AD8: =(M8+N8+O8)/B8 | AE8: =(F8+I8+J8+K8+L8+M8+N8+O8)/$B8 | AF8: =P8/$B8
A9: 6 | B9: 1 | C9: 2 | D9: 2 | E9: 0 | F9: 3 | G9: 90 | H9: 1 | I9: 0 | J9: 0 | K9: 0 | L9: 1 | M9: 0 | N9: 0 | O9: 0 | P9: 0 | R9: =D9/$B9 | S9: =E9/$B9 | T9: =F9/$B9 | U9: =G9-G8/$B9 | V9: =H9/$B9 | W9: =I9/$B9 | X9: =J9/$B9 | Y9: =K9/$B9 | Z9: =L9/$B9 | AA9: =M9/$B9 | AB9: =N9/$B9 | AC9: =O9/$B9 | AD9: =(M9+N9+O9)/B9 | AE9: =(F9+I9+J9+K9+L9+M9+N9+O9)/$B9 | AF9: =P9/$B9 | AM9: 13.5 | AN9: 0
A10: 7 | B10: 1 | C10: 2 | D10: 0 | E10: 5 | F10: 7 | G10: 105 | H10: 0 | I10: 0 | J10: 0 | K10: 0 | L10: 0 | M10: 0 | N10: 0 | O10: 0 | P10: 118 | R10: =D10/$B10 | S10: =E10/$B10 | T10: =F10/$B10 | U10: =G10-G9/$B10 | V10: =H10/$B10 | W10: =I10/$B10 | X10: =J10/$B10 | Y10: =K10/$B10 | Z10: =L10/$B10 | AA10: =M10/$B10 | AB10: =N10/$B10 | AC10: =O10/$B10 | AD10: =(M10+N10+O10)/B10 | AE10: =(F10+I10+J10+K10+L10+M10+N10+O10)/$B10 | AF10: =P10/$B10 | AM10: 13.5 | AN10: 1000
A11: 8 | B11: 1 | C11: 4 | D11: 0 | E11: 0 | F11: 0 | G11: 30 | H11: 1 | I11: 0 | J11: 0 | K11: 0 | L11: 1 | M11: 0 | N11: 0 | O11: 0 | P11: 1055 | R11: =D11/$B11 | S11: =E11/$B11 | T11: =F11/$B11 | U11: =G11-G10/$B11 | V11: =H11/$B11 | W11: =I11/$B11 | X11: =J11/$B11 | Y11: =K11/$B11 | Z11: =L11/$B11 | AA11: =M11/$B11 | AB11: =N11/$B11 | AC11: =O11/$B11 | AD11: =(M11+N11+O11)/B11 | AE11: =(F11+I11+J11+K11+L11+M11+N11+O11)/$B11 | AF11: =P11/$B11
A12: 9 | B12: 1 | C12: 4 | D12: 0 | E12: 2 | F12: 28 | G12: 410 | H12: 3 | I12: 1 | J12: 1 | K12: 1 | L12: 0 | M12: 0 | N12: 2 | O12: 1 | P12: 0 | R12: =D12/$B12 | S12: =E12/$B12 | T12: =F12/$B12 | U12: =G12-G11/$B12 | V12: =H12/$B12 | W12: =I12/$B12 | X12: =J12/$B12 | Y12: =K12/$B12 | Z12: =L12/$B12 | AA12: =M12/$B12 | AB12: =N12/$B12 | AC12: =O12/$B12 | AD12: =(M12+N12+O12)/B12 | AE12: =(F12+I12+J12+K12+L12+M12+N12+O12)/$B12 | AF12: =P12/$B12
A13: 10 | B13: 1 | C13: 4 | D13: 0 | E13: 1 | F13: 15 | G13: 410 | H13: 4 | I13: 1 | J13: 1 | K13: 0 | L13: 2 | M13: 0 | N13: 1 | O13: 1 | P13: 0 | R13: =D13/$B13 | S13: =E13/$B13 | T13: =F13/$B13 | U13: =G13-G12/$B13 | V13: =H13/$B13 | W13: =I13/$B13 | X13: =J13/$B13 | Y13: =K13/$B13 | Z13: =L13/$B13 | AA13: =M13/$B13 | AB13: =N13/$B13 | AC13: =O13/$B13 | AD13: =(M13+N13+O13)/B13 | AE13: =(F13+I13+J13+K13+L13+M13+N13+O13)/$B13 | AF13: =P13/$B13
A14: 11 | B14: 1 | D14: #N/A | E14: #N/A | F14: #N/A | G14: #N/A | H14: #N/A | I14: #N/A | J14: #N/A | K14: #N/A | L14: #N/A | M14: #N/A | N14: #N/A | O14: #N/A | P14: #N/A | R14: =D14/$B14 | S14: =E14/$B14 | T14: =F14/$B14 | U14: =G14/$B14 | V14: =H14/$B14 | W14: =I14/$B14 | X14: =J14/$B14 | Y14: =K14/$B14 | ... AC14: =O14/$B14 | AD14: =(M14+N14+O14)/B14 | AE14: =(F14+I14+J14+K14+L14+M14+N14+O14)/$B14 | AF14: =P14/$B14
A15: 12 | B15: 1 | D15: #N/A | E15: #N/A | F15: #N/A | G15: #N/A | H15: #N/A | I15: #N/A | J15: #N/A | K15: #N/A | L15: #N/A | M15: #N/A | N15: #N/A | O15: #N/A | P15: #N/A | R15: =D15/$B15 | S15: =E15/$B15 | T15: =F15/$B15 | U15: =G15/$B15 | V15: =H15/$B15 | W15: =I15/$B15 | X15: =J15/$B15 | Y15: =K15/$B15 | ... AC15: =O15/$B15 | AD15: =(M15+N15+O15)/B15 | AE15: =(F15+I15+J15+K15+L15+M15+N15+O15)/$B15 | AF15: =P15/$B15
A16: 13 | B16: 1 | D16: #N/A | E16: #N/A | F16: #N/A | G16: #N/A | H16: #N/A | I16: #N/A | J16: #N/A | K16: #N/A | L16: #N/A | M16: #N/A | N16: #N/A | O16: #N/A | P16: #N/A | R16: =D16/$B16 | S16: =E16/$B16 | T16: =F16/$B16 | U16: =G16/$B16 | V16: =H16/$B16 | W16: =I16/$B16 | X16: =J16/$B16 | Y16: =K16/$B16 | ... AC16: =O16/$B16 | AD16: =(M16+N16+O16)/B16 | AE16: =(F16+I16+J16+K16+L16+M16+N16+O16)/$B16 | AF16: =P16/$B16
A17: 14 | B17: 1 | D17: #N/A | E17: #N/A | F17: #N/A | G17: #N/A | H17: #N/A | I17: #N/A | J17: #N/A | K17: #N/A | L17: #N/A | M17: #N/A | N17: #N/A | O17: #N/A | P17: #N/A | R17: =D17/$B17 | S17: =E17/$B17 | T17: =F17/$B17 | U17: =G17/$B17 | V17: =H17/$B17 | W17: =I17/$B17 | X17: =J17/$B17 | Y17: =K17/$B17 | ... AC17: =O17/$B17 | AD17: =(M17+N17+O17)/B17 | AE17: =(F17+I17+J17+K17+L17+M17+N17+O17)/$B17 | AF17: =P17/$B17
A18: 15 | B18: 1 | D18: #N/A | E18: #N/A | F18: #N/A | G18: #N/A | H18: #N/A | I18: #N/A | J18: #N/A | K18: #N/A | L18: #N/A | M18: #N/A | N18: #N/A | O18: #N/A | P18: #N/A | R18: =D18/$B18 | S18: =E18/$B18 | T18: =F18/$B18 | U18: =G18/$B18 | V18: =H18/$B18 | W18: =I18/$B18 | X18: =J18/$B18 | Y18: =K18/$B18 | ... AC18: =O18/$B18 | AD18: =(M18+N18+O18)/B18 | AE18: =(F18+I18+J18+K18+L18+M18+N18+O18)/$B18 | AF18: =P18/$B18
A19: 16 | B19: 1 | D19: #N/A | E19: #N/A | F19: #N/A | G19: #N/A | H19: #N/A | I19: #N/A | J19: #N/A | K19: #N/A | L19: #N/A | M19: #N/A | N19: #N/A | O19: #N/A | P19: #N/A | R19: =D19/$B19 | S19: =E19/$B19 | T19: =F19/$B19 | U19: =G19/$B19 | V19: =H19/$B19 | W19: =I19/$B19 | X19: =J19/$B19 | Y19: =K19/$B19 | ... AC19: =O19/$B19 | AD19: =(M19+N19+O19)/B19 | AE19: =(F19+I19+J19+K19+L19+M19+N19+O19)/$B19 | AF19: =P19/$B19
A20: 17 | B20: 1 | D20: #N/A | E20: #N/A | F20: #N/A | G20: #N/A | H20: #N/A | I20: #N/A | J20: #N/A | K20: #N/A | L20: #N/A | M20: #N/A | N20: #N/A | O20: #N/A | P20: #N/A | R20: =D20/$B20 | S20: =E20/$B20 | T20: =F20/$B20 | U20: =G20/$B20 | V20: =H20/$B20 | W20: =I20/$B20 | X20: =J20/$B20 | Y20: =K20/$B20 | ... AC20: =O20/$B20 | AD20: =(M20+N20+O20)/B20 | AE20: =(F20+I20+J20+K20+L20+M20+N20+O20)/$B20 | AF20: =P20/$B20
A21: 18 | B21: 1 | D21: #N/A | E21: #N/A | F21: #N/A | G21: #N/A | H21: #N/A | I21: #N/A | J21: #N/A | K21: #N/A | L21: #N/A | M21: #N/A | N21: #N/A | O21: #N/A | P21: #N/A | R21: =D21/$B21 | S21: =E21/$B21 | T21: =F21/$B21 | U21: =G21/$B21 | V21: =H21/$B21 | W21: =I21/$B21 | X21: =J21/$B21 | Y21: =K21/$B21 | ... AC21: =O21/$B21 | AD21: =(M21+N21+O21)/B21 | AE21: =(F21+I21+J21+K21+L21+M21+N21+O21)/$B21 | AF21: =P21/$B21
A22: 19 | B22: 1 | D22: #N/A | E22: #N/A | F22: #N/A | G22: #N/A | H22: #N/A | I22: #N/A | J22: #N/A | K22: #N/A | L22: #N/A | M22: #N/A | N22: #N/A | O22: #N/A | P22: #N/A | R22: =D22/$B22 | S22: =E22/$B22 | T22: =F22/$B22 | U22: =G22/$B22 | V22: =H22/$B22 | W22: =I22/$B22 | X22: =J22/$B22 | Y22: =K22/$B22 | ... AC22: =O22/$B22 | AD22: =(M22+N22+O22)/B22 | AE22: =(F22+I22+J22+K22+L22+M22+N22+O22)/$B22 | AF22: =P22/$B22
A23: 20 | B23: 1 | D23: #N/A | E23: #N/A | F23: #N/A | G23: #N/A | H23: #N/A | I23: #N/A | J23: #N/A | K23: #N/A | L23: #N/A | M23: #N/A | N23: #N/A | O23: #N/A | P23: #N/A | R23: =D23/$B23 | S23: =E23/$B23 | T23: =F23/$B23 | U23: =G23/$B23 | V23: =H23/$B23 | W23: =I23/$B23 | X23: =J23/$B23 | Y23: =K23/$B23 | ... AC23: =O23/$B23 | AD23: =(M23+N23+O23)/B23 | AE23: =(F23+I23+J23+K23+L23+M23+N23+O23)/$B23 | AF23: =P23/$B23
A24: 21 | B24: 1 | D24: #N/A | E24: #N/A | F24: #N/A | G24: #N/A | H24: #N/A | I24: #N/A | J24: #N/A | K24: #N/A | L24: #N/A | M24: #N/A | N24: #N/A | O24: #N/A | P24: #N/A | R24: =D24/$B24 | S24: =E24/$B24 | T24: =F24/$B24 | U24: =G24/$B24 | V24: =H24/$B24 | W24: =I24/$B24 | X24: =J24/$B24 | Y24: =K24/$B24 | ... AC24: =O24/$B24 | AD24: =(M24+N24+O24)/B24 | AE24: =(F24+I24+J24+K24+L24+M24+N24+O24)/$B24 | AF24: =P24/$B24
A25: 22 | B25: 1 | D25: #N/A | E25: #N/A | F25: #N/A | G25: #N/A | H25: #N/A | I25: #N/A | J25: #N/A | K25: #N/A | L25: #N/A | M25: #N/A | N25: #N/A | O25: #N/A | P25: #N/A | R25: =D25/$B25 | S25: =E25/$B25 | T25: =F25/$B25 | U25: =G25/$B25 | V25: =H25/$B25 | W25: =I25/$B25 | X25: =J25/$B25 | Y25: =K25/$B25 | ... AC25: =O25/$B25 | AD25: =(M25+N25+O25)/B25 | AE25: =(F25+I25+J25+K25+L25+M25+N25+O25)/$B25 | AF25: =P25/$B25
... A76: 73 | B76: 1 | D76: #N/A | E76: #N/A | F76: #N/A | G76: #N/A | H76: #N/A | I76: #N/A | J76: #N/A | K76: #N/A | L76: #N/A | M76: #N/A | N76: #N/A | O76: #N/A | P76: #N/A | R76: =D76/$B76 | S76: =E76/$B76 | T76: =F76/$B76 | U76: =G76/$B76 | V76: =H76/$B76 | W76: =I76/$B76 | X76: =J76/$B76 | Y76: =K76/$B76 | ... AC76: =O76/$B76 | AD76: =(M76+N76+O76)/B76 | AE76: =(F76+I76+J76+K76+L76+M76+N76+O76)/$B76 | AF76: =P76/$B76

Sheet Session by Session
D1: BSL | E1: BSL | F1: Target | H1: Alt | I1: Alt | J1: Target | L1: Asteroids | M1: Barrel Roll | N1: Spin | O1: Speed | P1: Coin | Q1: Flame | R1: Red | S1: Blue | T1: Yellow | U1: Tokens | V1: Crash | X1: Phase Lines | AA1: Dotted PL
A2: Session # | B2: Condition | D2: Rate | E2: Reinf | F2: Rate | H2: Rate | I2: Reinf | J2: Rate | L2: Freq | M2: Freq | N2: Freq | O2: Freq | P2: Freq | Q2: Freq | R2: Freq | S2: Freq | T2: Freq | U2: Combined | V2: Freq | X2: 4.5 | Y2: 0 | AA2: 11.5 | AB2: 0
A3: 1 | B3: ='Data Entry'!B6 | C3: 1 | D3: ='Data Entry'!C8 | E3: ='Data Entry'!C11 | F3: =D3 | H3: #N/A | I3: #N/A | J3: #N/A | L3: ='Data Entry'!B10 | M3: ='Data Entry'!$G7 | N3: ='Data Entry'!$G8 | O3: ='Data Entry'!$G16 | P3: ='Data Entry'!$G10 | Q3: ='Data Entry'!I7 | R3: ='Data Entry'!I15 | S3: ='Data Entry'!I9 | T3: ='Data Entry'!I10 | U3: =R3+S3+T3 | V3: ='Data Entry'!I11 | X3: 4.5 | Y3: 1000 | AA3: 11.5 | AB3: 1000
A4: 2 | B4: ='Data Entry'!B13 | C4: 2 | D4: ='Data Entry'!C15 | E4: ='Data Entry'!C18 | F4: =D4 | H4: #N/A | I4: #N/A | J4: #N/A | L4: ='Data Entry'!B17 | M4: ='Data Entry'!$G14 | N4: ='Data Entry'!$G15 | O4: ='Data Entry'!$G10 | P4: ='Data Entry'!$G16 | Q4: ='Data Entry'!I14 | R4: ='Data Entry'!I15 | S4: ='Data Entry'!I16 | T4: ='Data Entry'!I17 | U4: =R4+S4+T4 | V4: ='Data Entry'!I18
A5: 3 | B5: ='Data Entry'!B20 | C5: 3 | D5: ='Data Entry'!C22 | E5: ='Data Entry'!C25 | F5: =D5 | H5: #N/A | I5: #N/A | J5: #N/A | L5: ='Data Entry'!B24 | M5: ='Data Entry'!$G21 | N5: ='Data Entry'!$G22 | O5: ='Data Entry'!$G23 | P5: ='Data Entry'!$G24 | Q5: ='Data Entry'!I21 | R5: ='Data Entry'!I22 | S5: ='Data Entry'!I23 | T5: ='Data Entry'!I24 | U5: =R5+S5+T5 | V5: ='Data Entry'!I25 | X5: 7.5 | Y5: 0 | AA5: 12.5 | AB5: 0
A6: 4 | B6: ='Data Entry'!B45 | C6: 4 | D6: ='Data Entry'!C29 | E6: ='Data Entry'!C29 | F6: =D6 | H6: ='Data Entry'!C31 | I6: ='Data Entry'!C33 | J6: #N/A | L6: ='Data Entry'!B32 | M6: ='Data Entry'!$G28 | N6: ='Data Entry'!$G29 | O6: ='Data Entry'!$G30 | P6: ='Data Entry'!$G31 | Q6: ='Data Entry'!I28 | R6: ='Data Entry'!I29 | S6: ='Data Entry'!I30 | T6: ='Data Entry'!I31 | U6: =R6+S6+T6 | V6: ='Data Entry'!I32 | X6: 7.5 | Y6: 1000 | AA6: 12.5 | AB6: 1000
A7: 5 | B7: ='Data Entry'!B53 | C7: 5 | D7: ='Data Entry'!$C37 | E7: 0 | F7: =D7 | H7: ='Data Entry'!C39 | I7: ='Data Entry'!C41 | J7: #N/A | L7: ='Data Entry'!B40 | M7: ='Data Entry'!$G36 | N7: ='Data Entry'!$G37 | O7: ='Data Entry'!$G38 | P7: ='Data Entry'!$G39 | Q7: ='Data Entry'!I36 | R7: ='Data Entry'!I37 | S7: ='Data Entry'!I38 | T7: ='Data Entry'!I39 | U7: =R7+S7+T7 | V7: ='Data Entry'!I40
A8: 6 | B8: ='Data Entry'!B61 | C8: 6 | D8: ='Data Entry'!$C47 | E8: 0 | F8: ='Data Entry'!C47 | H8: ='Data Entry'!$C48 | I8: ='Data Entry'!$C50 | J8: =D8 | L8: ='Data Entry'!B49 | M8: ='Data Entry'!$G45 | N8: ='Data Entry'!$G46 | O8: ='Data Entry'!$G47 | P8: ='Data Entry'!$G48 | Q8: ='Data Entry'!I45 | R8: ='Data Entry'!I46 | S8: ='Data Entry'!I47 | T8: ='Data Entry'!I48 | U8: =R8+S8+T8 | V8: ='Data Entry'!I49 | AA8: 13.5 | AB8: 0
A9: 7 | B9: Alternative 2 | C9: 7 | D9: ='Data Entry'!$C55 | E9: 0 | F9: ='Data Entry'!C55 | H9: ='Data Entry'!$C56 | I9: ='Data Entry'!$C58 | J9: =D9 | L9: ='Data Entry'!B57 | M9: ='Data Entry'!$G53 | N9: ='Data Entry'!$G54 | O9: ='Data Entry'!$G55 | P9: ='Data Entry'!$G56 | Q9: ='Data Entry'!I53 | R9: ='Data Entry'!I54 | S9: ='Data Entry'!I55 | T9: ='Data Entry'!I56 | U9: =R9+S9+T9 | V9: ='Data Entry'!I57 | AA9: 13.5 | AB9: 1000
A10: 8 | B10: Alternative 1 | C10: 8 | D10: ='Data Entry'!$C63 | E10: 0 | F10: ='Data Entry'!C63 | H10: ='Data Entry'!$C64 | I10: ='Data Entry'!$C66 | J10: =D10 | L10: ='Data Entry'!B65 | M10: ='Data Entry'!$G61 | N10: ='Data Entry'!$G62 | O10: ='Data Entry'!$G63 | P10: ='Data Entry'!$G64 | Q10: ='Data Entry'!I61 | R10: ='Data Entry'!I62 | S10: ='Data Entry'!I63 | T10: ='Data Entry'!I64 | U10: =R10+S10+T10 | V10: ='Data Entry'!I65
A11: 9 | B11: Alternative 2 | C11: 9 | D11: ='Data Entry'!$C71 | E11: 0 | F11: ='Data Entry'!C71 | H11: ='Data Entry'!$C72 | I11: ='Data Entry'!$C74 | J11: =D11 | L11: ='Data Entry'!B73 | M11: ='Data Entry'!$G69 | N11: ='Data Entry'!$G70 | O11: ='Data Entry'!$G71 | P11: ='Data Entry'!$G72 | Q11: ='Data Entry'!I69 | R11: ='Data Entry'!I70 | S11: ='Data Entry'!I71 | T11: ='Data Entry'!I72 | U11: =R11+S11+T11 | V11: ='Data Entry'!I73
A12: 10 | B12: PA | C12: 10 | D12: ='Data Entry'!$C72 | E12: 0 | F12: ='Data Entry'!C72 | H12: ='Data Entry'!$C80 | I12: ='Data Entry'!$C75 | J12: =D12 | L12: ='Data Entry'!B81 | M12: ='Data Entry'!$G77 | N12: ='Data Entry'!$G78 | O12: ='Data Entry'!$G79 | P12: ='Data Entry'!$G80 | Q12: ='Data Entry'!I77 | R12: ='Data Entry'!I78 | S12: ='Data Entry'!I79 | T12: ='Data Entry'!I80 | U12: =R12+S12+T12 | V12: ='Data Entry'!I81
A13: 11 | B13: Booster Session
A14: 12 | B14: Alternative 1
A15: 13 | B15: Alternative 2
A16: 14 | B16: Alternative 1
A17: 15 | B17: Alternative 2
A18: 16 | B18: Alternative 1
A19: 17 | B19: Alternative 2
A20: 18 | B20: Alternative 1
A21: 19 | B21: Alternative 2
A22: 20 | B22: Alternative 1
A23: 21 | B23: Alternative 2
A24: 22 | B24: Alternative 1
A25: 23 | B25: Alternative 2

Sheet Sheet2
A1: Baseline | E1: Baseline
A2: Treatment | E2: Treatment
A3: Step 1 | E3: Thinning
A4: Step 2 | E4: Extinction
A5: Step 3
A7: SD1
A8: Sdelta
A9: SD2
