Workbook

Sheet Data Entry
A1: DATA ENTRY
K4: Initials of person entering data: | M4: Initials of person checking data:
A6: Phase | B6: Baseline | E6: IOA | F6: Power Ups | G6: Freq | H6: Power Ups | I6: Freq
A7: Trial Type | B7: Baseline | C7: Resp per Min | F7: Barrel Roll | G7: 3 | H7: Flame Change | I7: 2
A8: Session | B8: 1 | C8: =B9 -> 28 | E8: IOA | F8: Spins | G8: 2 | H8: Red token | I8: 0
A9: Target Resp | B9: 28 | E9: Y/E | F9: Speed Boosts | G9: 0 | H9: Blue Token | I9: 0
A10: Asteroids | B10: 30 | C10: Reinf per Min | E10: Y/E | F10: Coin Boost | G10: 2 | H10: Yellow Token | I10: 1
A11: Total Points: | B11: 45 | C11: =((B11/5)) -> 9 | E11: Y/E | H11: Crash | I11: 63 | AI11: Alt 1 | AJ11: Alt 2 | AK11: target 1 | AL11: Target 2
A13: Phase | B13: Baseline | F13: Power Ups | G13: Freq | H13: Power Ups | I13: Freq | AH13: 2 | AI13: 0.288 | AJ13: 1.9920949 | AK13: 0.31034483 | AL13: 0.051724138
A14: Trial Type | B14: Baseline | C14: Resp per Min | F14: Barrel Roll | G14: 3 | H14: Flame Change | I14: 0 | AH14: 3 | AI14: 0.192 | AJ14: 0.45059289 | AK14: 0.077586207 | AL14: 0.025862069
A15: Session | B15: =B8+1 -> 2 | C15: =B16 -> 24 | E15: IOA | F15: Spins | G15: 2 | H15: Red token | I15: 1
A16: Target Resp | B16: 24 | E16: Y/E | F16: Speed Boosts | G16: 1 | H16: Blue Token | I16: 1 | AH16: Slope | AI16: -0.672 | AJ16: -0.65217391 | AK16: -0.86637931 | AL16: -0.064655172
A17: Asteroids | B17: 13 | C17: Reinf per Min | E17: Y/E | F17: Coin Boost | G17: 1 | H17: Yellow Token | I17: 1
A18: Total Points: | B18: 75 | C18: =(((B18-B11)/5)) -> 6 | D18: =B18/5 -> 15 | E18: Y/E | H18: Crash | I18: 0 | AH18: N | AI18: 3 | AJ18: 3 | AK18: 3 | AL18: 3
AH19: Se(reg) | AI19: 0.47030203 | AJ19: 0.72613332 | AK19: 0.51734913 | AL19: 0.031674436
A20: Phase | B20: Baseline | F20: Power Ups | G20: Freq | H20: Power Ups | I20: Freq | AH20: SE (slope) | AI20: 0.33255376 | AJ20: 0.5134538 | AK20: 0.36582108 | AL20: 0.022397209
A21: Trial Type | B21: Baseline | C21: Resp per Min | F21: Barrel Roll | G21: 3 | H21: Flame Change | I21: 1 | AI21: Dif | AJ21: 0.019826087 | AK21: Dif | AL21: 0.80172414
A22: Session | B22: =B15+1 -> 3 | C22: =B23 -> 11 | E22: IOA | F22: Spins | G22: 2 | H22: Red token | I22: 0 | AI22: SE (Dif) | AJ22: 0.6117408 | AK22: SE (Dif) | AL22: 0.36650606
A23: Target Resp | B23: 11 | E23: Y/E | F23: Speed Boosts | G23: 1 | H23: Blue Token | I23: 0 | AI23: T-stat | AJ23: 0.032409293 | AK23: T-stat | AL23: 2.1874785
A24: Asteroids | B24: 22 | C24: Reinf per Min | E24: Y/E | F24: Coin Boost | G24: 0 | H24: Yellow Token | I24: 0
A25: Total Points: | B25: 95 | C25: =(((B25-B18)/5)) -> 4 | D25: =B25/5 -> 19 | E25: Y/E | H25: Crash | I25: 18 | AI25: DF | AJ25: 4 | AK25: DF | AL25: 4
AI26: P | AJ26: 0.97569835 | AK26: P | AL26: 0.093956212
A27: Phase | B27: Treatment | F27: Power Ups | G27: Freq | H27: Power Ups | I27: Freq
A28: Trial Type | B28: Treatment | C28: Resp per Min | F28: Barrel Roll | G28: 4 | H28: Flame Change | I28: 1
A29: Session | B29: =B22+1 -> 4 | C29: =B30 -> 5 | E29: IOA | F29: Spins | G29: 2 | H29: Red token | I29: 0
A30: Target Resp | B30: 5 | E30: Y/E | F30: Speed Boosts | G30: 0 | H30: Blue Token | I30: 0
A31: Alt resp | B31: 27 | C31: =B31 -> 27 | E31: Y/E | F31: Coin Boost | G31: 2 | H31: Yellow Token | I31: 1
A32: Asteroids | B32: 44 | C32: Reinf per Min | E32: Y/E | H32: Crash | I32: 1
A33: Total Points: | B33: 145 | C33: =(((B33-B25)/5)/2) -> 5 | D33: =B33/5 -> 29 | E33: Y/E
A35: Phase | B35: Treatment | F35: Power Ups | G35: Freq | H35: Power Ups | I35: Freq
A36: Trial Type | B36: Treatment | C36: Resp per Min | F36: Barrel Roll | G36: 2 | H36: Flame Change | I36: 0
A37: Session | B37: =B29+1 -> 5 | C37: =B38 -> 0 | E37: IOA | F37: Spins | G37: 0 | H37: Red token | I37: 1
A38: Target Resp | B38: 0 | E38: Y/E | F38: Speed Boosts | G38: 2 | H38: Blue Token | I38: 0
A39: Alt Resp | B39: 41 | C39: =B39 -> 41 | E39: Y/E | F39: Coin Boost | G39: 2 | H39: Yellow Token | I39: 0
A40: Asteroids | B40: 42 | C40: Reinf per Min | E40: Y/E | H40: Crash | I40: 3
A41: Total Points: | B41: 190 | C41: =(((B41-B33)/5)/2) -> 4.5 | D41: =B41/5 -> 38 | E41: Y/E
A44: Phase | B44: Treatment | C44: Responses/Reinf Per Min | F44: Power Ups | G44: Freq | H44: Power Ups | I44: Freq
A45: Trial Type | B45: Treatment | F45: Barrel Roll | G45: 3 | H45: Flame Change | I45: 1
A46: Session | B46: =B37+1 -> 6 | E46: IOA | F46: Spins | G46: 2 | H46: Red token | I46: 0
A47: Target Resp | B47: 0 | C47: =B47 -> 0 | E47: Y/E | F47: Speed Boosts | G47: 1 | H47: Blue Token | I47: 0
...

Sheet Session by Session
D1: BSL | E1: BSL | F1: Target | H1: Alt | I1: Alt | J1: Target | L1: Asteroids | M1: Barrel Roll | N1: Spin | O1: Speed | P1: Coin | Q1: Flame | R1: Red | S1: Blue | T1: Yellow | U1: Tokens | V1: Crash | X1: Phase Lines | AA1: Dotted PL
A2: Session # | B2: Condition | D2: Rate | E2: Reinf | F2: Rate | H2: Rate | I2: Reinf | J2: Rate | L2: Freq | M2: Freq | N2: Freq | O2: Freq | P2: Freq | Q2: Freq | R2: Freq | S2: Freq | T2: Freq | U2: Combined | V2: Freq | X2: 3.5 | Y2: 0 | AA2: 11.5 | AB2: 0
A3: 1 | B3: ='Data Entry'!B6 -> Baseline | C3: 1 | D3: ='Data Entry'!C8 -> 28 | E3: ='Data Entry'!C11 -> 9 | F3: =D3 -> 28 | H3: #N/A | I3: #N/A | J3: #N/A | L3: ='Data Entry'!B10 -> 30 | M3: ='Data Entry'!$G7 -> 3 | N3: ='Data Entry'!$G8 -> 2 | O3: ='Data Entry'!$G16 -> 1 | P3: ='Data Entry'!$G10 -> 2 | Q3: ='Data Entry'!I7 -> 2 | R3: ='Data Entry'!I15 -> 1 | S3: ='Data Entry'!I9 -> 0 | T3: ='Data Entry'!I10 -> 1 | U3: =R3+S3+T3 -> 2 | V3: ='Data Entry'!I11 -> 63 | X3: 3.5 | Y3: 1000 | AA3: 11.5 | AB3: 1000
A4: 2 | B4: ='Data Entry'!B13 -> Baseline | C4: 2 | D4: ='Data Entry'!C15 -> 24 | E4: ='Data Entry'!C18 -> 6 | F4: =D4 -> 24 | H4: #N/A | I4: #N/A | J4: #N/A | L4: ='Data Entry'!B17 -> 13 | M4: ='Data Entry'!$G14 -> 3 | N4: ='Data Entry'!$G15 -> 2 | O4: ='Data Entry'!$G10 -> 2 | P4: ='Data Entry'!$G16 -> 1 | Q4: ='Data Entry'!I14 -> 0 | R4: ='Data Entry'!I15 -> 1 | S4: ='Data Entry'!I16 -> 1 | T4: ='Data Entry'!I17 -> 1 | U4: =R4+S4+T4 -> 3 | V4: ='Data Entry'!I18 -> 0
A5: 3 | B5: ='Data Entry'!B20 -> Baseline | C5: 3 | D5: ='Data Entry'!C22 -> 11 | E5: ='Data Entry'!C25 -> 4 | F5: =D5 -> 11 | H5: #N/A | I5: #N/A | J5: #N/A | L5: ='Data Entry'!B24 -> 22 | M5: ='Data Entry'!$G21 -> 3 | N5: ='Data Entry'!$G22 -> 2 | O5: ='Data Entry'!$G23 -> 1 | P5: ='Data Entry'!$G24 -> 0 | Q5: ='Data Entry'!I21 -> 1 | R5: ='Data Entry'!I22 -> 0 | S5: ='Data Entry'!I23 -> 0 | T5: ='Data Entry'!I24 -> 0 | U5: =R5+S5+T5 -> 0 | V5: ='Data Entry'!I25 -> 18 | X5: 6.5 | Y5: 0 | AA5: 12.5 | AB5: 0
A6: 4 | B6: ='Data Entry'!B45 -> Treatment | C6: 4 | D6: ='Data Entry'!C29 -> 5 | E6: 0 | F6: =D6 -> 5 | H6: ='Data Entry'!C31 -> 27 | I6: ='Data Entry'!C33 -> 5 | J6: #N/A | L6: ='Data Entry'!B32 -> 44 | M6: ='Data Entry'!$G28 -> 4 | N6: ='Data Entry'!$G29 -> 2 | O6: ='Data Entry'!$G30 -> 0 | P6: ='Data Entry'!$G31 -> 2 | Q6: ='Data Entry'!I28 -> 1 | R6: ='Data Entry'!I29 -> 0 | S6: ='Data Entry'!I30 -> 0 | T6: ='Data Entry'!I31 -> 1 | U6: =R6+S6+T6 -> 1 | V6: ='Data Entry'!I32 -> 1 | X6: 6.5 | Y6: 1000 | AA6: 12.5 | AB6: 1000
A7: 5 | B7: ='Data Entry'!B53 -> Treatment | C7: 5 | D7: ='Data Entry'!$C37 -> 0 | E7: 0 | F7: =D7 -> 0 | H7: ='Data Entry'!C39 -> 41 | I7: ='Data Entry'!C41 -> 4.5 | J7: #N/A | L7: ='Data Entry'!B40 -> 42 | M7: ='Data Entry'!$G36 -> 2 | N7: ='Data Entry'!$G37 -> 0 | O7: ='Data Entry'!$G38 -> 2 | P7: ='Data Entry'!$G39 -> 2 | Q7: ='Data Entry'!I36 -> 0 | R7: ='Data Entry'!I37 -> 1 | S7: ='Data Entry'!I38 -> 0 | T7: ='Data Entry'!I39 -> 0 | U7: =R7+S7+T7 -> 1 | V7: ='Data Entry'!I40 -> 3
A8: 6 | B8: ='Data Entry'!B61 -> Treatment | C8: 6 | D8: ='Data Entry'!$C47 -> 0 | E8: 0 | F8: ='Data Entry'!C47 -> 0 | H8: ='Data Entry'!$C48 -> 34 | I8: ='Data Entry'!$C50 -> 5.5 | J8: =D8 -> 0 | L8: ='Data Entry'!B49 -> 57 | M8: ='Data Entry'!$G45 -> 3 | N8: ='Data Entry'!$G46 -> 2 | O8: ='Data Entry'!$G47 -> 1 | P8: ='Data Entry'!$G48 -> 1 | Q8: ='Data Entry'!I45 -> 1 | R8: ='Data Entry'!I46 -> 0 | S8: ='Data Entry'!I47 -> 0 | T8: ='Data Entry'!I48 -> 0 | U8: =R8+S8+T8 -> 0 | V8: ='Data Entry'!I49 -> 120 | AA8: 13.5 | AB8: 0
A9: 7 | B9: Alternative 2 | C9: 7 | D9: ='Data Entry'!$C55 -> 12 | E9: 0 | F9: ='Data Entry'!C55 -> 12 | H9: ='Data Entry'!$C56 -> 24 | I9: ='Data Entry'!$C58 -> 0 | J9: =D9 -> 12 | L9: ='Data Entry'!B57 -> 74 | M9: ='Data Entry'!$G53 -> 5 | N9: ='Data Entry'!$G54 -> 3 | O9: ='Data Entry'!$G55 -> 2 | P9: ='Data Entry'!$G56 -> 2 | Q9: ='Data Entry'!I53 -> 2 | R9: ='Data Entry'!I54 -> 0 | S9: ='Data Entry'!I55 -> 1 | T9: ='Data Entry'!I56 -> 0 | U9: =R9+S9+T9 -> 1 | V9: ='Data Entry'!I57 -> 139 | AA9: 13.5 | AB9: 1000
A10: 8 | B10: Alternative 1 | C10: 8 | D10: ='Data Entry'!$C63 -> 0 | E10: 0 | F10: ='Data Entry'!C63 -> 0 | H10: ='Data Entry'!$C64 -> 3 | I10: ='Data Entry'!$C66 -> 0 | J10: =D10 -> 0 | L10: ='Data Entry'!B65 -> 3 | M10: ='Data Entry'!$G61 -> 1 | N10: ='Data Entry'!$G62 -> 1 | O10: ='Data Entry'!$G63 -> 0 | P10: ='Data Entry'!$G64 -> 0 | Q10: ='Data Entry'!I61 -> 0 | R10: ='Data Entry'!I62 -> 1 | S10: ='Data Entry'!I63 -> 0 | T10: ='Data Entry'!I64 -> 0 | U10: =R10+S10+T10 -> 1 | V10: ='Data Entry'!I65 -> 0
A11: 9 | B11: Alternative 2 | C11: 9 | D11: ='Data Entry'!$C71 -> 0 | E11: 0 | F11: ='Data Entry'!C71 -> 0 | H11: ='Data Entry'!$C72 -> 0 | I11: ='Data Entry'!$C74 -> 0 | J11: =D11 -> 0 | L11: ='Data Entry'!B73 -> 2 | M11: ='Data Entry'!$G69 -> 1 | N11: ='Data Entry'!$G70 -> 0 | O11: ='Data Entry'!$G71 -> 0 | P11: ='Data Entry'!$G72 -> 0 | Q11: ='Data Entry'!I69 -> 0 | R11: ='Data Entry'!I70 -> 0 | S11: ='Data Entry'!I71 -> 0 | T11: ='Data Entry'!I72 -> 0 | U11: =R11+S11+T11 -> 0 | V11: ='Data Entry'!I73 -> 0
A12: 10 | B12: PA
A13: 11 | B13: Booster Session
A14: 12 | B14: Alternative 1
A15: 13 | B15: Alternative 2
A16: 14 | B16: Alternative 1
A17: 15 | B17: Alternative 2
A18: 16 | B18: Alternative 1
A19: 17 | B19: Alternative 2
A20: 18 | B20: Alternative 1
A21: 19 | B21: Alternative 2
A22: 20 | B22: Alternative 1
A23: 21 | B23: Alternative 2
... A25: 23 | B25: Alternative 2

Sheet Sheet2
A1: Baseline | E1: Baseline
A2: Treatment | E2: Treatment
A3: Step 1 | E3: Thinning
A4: Step 2 | E4: Extinction
A5: Step 3
A7: SD1
A8: Sdelta
A9: SD2
